Workbook

Sheet Loan EMI
A1: Loan EMI Calculator
A4: Loan amount | B4: 5000000
A5: Annual interest rate | B5: 0.085
A6: Tenure (years) | B6: 20
A8: Results
A9: Monthly interest rate | B9: =B5/12 -> 0.0070833333
A10: Number of months | B10: =B6*12 -> 240
A11: Monthly EMI | B11: =IFERROR(PMT(B9,B10,-B4),0) -> 43391.162
A12: Total payment | B12: =B11*B10 -> 10413879
A13: Total interest | B13: =B12-B4 -> 5413878.8
A14: Interest as % of loan | B14: =IFERROR(B13/B4,0) -> 1.0827758

Sheet Amortization
A1: Amortization Schedule (linked to Loan EMI sheet, up to 30 years)
A3: Month | B3: Opening balance | C3: EMI | D3: Interest | E3: Principal | F3: Closing balance
A4: =IF(1<='Loan EMI'!$B$10,1,"") -> 1 | B4: =IF(A4="","",'Loan EMI'!$B$4) -> 5000000 | C4: =IF(A4="","",'Loan EMI'!$B$11) -> 43391.162 | D4: =IF(A4="","",B4*'Loan EMI'!$B$9) -> 35416.667 | E4: =IF(A4="","",C4-D4) -> 7974.495 | F4: =IF(A4="","",MAX(B4-E4,0)) -> 4992025.5
A5: =IF(2<='Loan EMI'!$B$10,2,"") -> 2 | B5: =IF(A5="","",F4) -> 4992025.5 | C5: =IF(A5="","",'Loan EMI'!$B$11) -> 43391.162 | D5: =IF(A5="","",B5*'Loan EMI'!$B$9) -> 35360.181 | E5: =IF(A5="","",C5-D5) -> 8030.981 | F5: =IF(A5="","",MAX(B5-E5,0)) -> 4983994.5
A6: =IF(3<='Loan EMI'!$B$10,3,"") -> 3 | B6: =IF(A6="","",F5) -> 4983994.5 | C6: =IF(A6="","",'Loan EMI'!$B$11) -> 43391.162 | D6: =IF(A6="","",B6*'Loan EMI'!$B$9) -> 35303.295 | E6: =IF(A6="","",C6-D6) -> 8087.8671 | F6: =IF(A6="","",MAX(B6-E6,0)) -> 4975906.7
A7: =IF(4<='Loan EMI'!$B$10,4,"") -> 4 | B7: =IF(A7="","",F6) -> 4975906.7 | C7: =IF(A7="","",'Loan EMI'!$B$11) -> 43391.162 | D7: =IF(A7="","",B7*'Loan EMI'!$B$9) -> 35246.005 | E7: =IF(A7="","",C7-D7) -> 8145.1562 | F7: =IF(A7="","",MAX(B7-E7,0)) -> 4967761.5
A8: =IF(5<='Loan EMI'!$B$10,5,"") -> 5 | B8: =IF(A8="","",F7) -> 4967761.5 | C8: =IF(A8="","",'Loan EMI'!$B$11) -> 43391.162 | D8: =IF(A8="","",B8*'Loan EMI'!$B$9) -> 35188.311 | E8: =IF(A8="","",C8-D8) -> 8202.851 | F8: =IF(A8="","",MAX(B8-E8,0)) -> 4959558.7
A9: =IF(6<='Loan EMI'!$B$10,6,"") -> 6 | B9: =IF(A9="","",F8) -> 4959558.7 | C9: =IF(A9="","",'Loan EMI'!$B$11) -> 43391.162 | D9: =IF(A9="","",B9*'Loan EMI'!$B$9) -> 35130.207 | E9: =IF(A9="","",C9-D9) -> 8260.9546 | F9: =IF(A9="","",MAX(B9-E9,0)) -> 4951297.7
A10: =IF(7<='Loan EMI'!$B$10,7,"") -> 7 | B10: =IF(A10="","",F9) -> 4951297.7 | C10: =IF(A10="","",'Loan EMI'!$B$11) -> 43391.162 | D10: =IF(A10="","",B10*'Loan EMI'!$B$9) -> 35071.692 | E10: =IF(A10="","",C10-D10) -> 8319.4697 | F10: =IF(A10="","",MAX(B10-E10,0)) -> 4942978.2
A11: =IF(8<='Loan EMI'!$B$10,8,"") -> 8 | B11: =IF(A11="","",F10) -> 4942978.2 | C11: =IF(A11="","",'Loan EMI'!$B$11) -> 43391.162 | D11: =IF(A11="","",B11*'Loan EMI'!$B$9) -> 35012.762 | E11: =IF(A11="","",C11-D11) -> 8378.3992 | F11: =IF(A11="","",MAX(B11-E11,0)) -> 4934599.8
A12: =IF(9<='Loan EMI'!$B$10,9,"") -> 9 | B12: =IF(A12="","",F11) -> 4934599.8 | C12: =IF(A12="","",'Loan EMI'!$B$11) -> 43391.162 | D12: =IF(A12="","",B12*'Loan EMI'!$B$9) -> 34953.415 | E12: =IF(A12="","",C12-D12) -> 8437.7462 | F12: =IF(A12="","",MAX(B12-E12,0)) -> 4926162.1
A13: =IF(10<='Loan EMI'!$B$10,10,"") -> 10 | B13: =IF(A13="","",F12) -> 4926162.1 | C13: =IF(A13="","",'Loan EMI'!$B$11) -> 43391.162 | D13: =IF(A13="","",B13*'Loan EMI'!$B$9) -> 34893.648 | E13: =IF(A13="","",C13-D13) -> 8497.5136 | F13: =IF(A13="","",MAX(B13-E13,0)) -> 4917664.6
A14: =IF(11<='Loan EMI'!$B$10,11,"") -> 11 | B14: =IF(A14="","",F13) -> 4917664.6 | C14: =IF(A14="","",'Loan EMI'!$B$11) -> 43391.162 | D14: =IF(A14="","",B14*'Loan EMI'!$B$9) -> 34833.457 | E14: =IF(A14="","",C14-D14) -> 8557.7043 | F14: =IF(A14="","",MAX(B14-E14,0)) -> 4909106.9
A15: =IF(12<='Loan EMI'!$B$10,12,"") -> 12 | B15: =IF(A15="","",F14) -> 4909106.9 | C15: =IF(A15="","",'Loan EMI'!$B$11) -> 43391.162 | D15: =IF(A15="","",B15*'Loan EMI'!$B$9) -> 34772.84 | E15: =IF(A15="","",C15-D15) -> 8618.3214 | F15: =IF(A15="","",MAX(B15-E15,0)) -> 4900488.5
A16: =IF(13<='Loan EMI'!$B$10,13,"") -> 13 | B16: =IF(A16="","",F15) -> 4900488.5 | C16: =IF(A16="","",'Loan EMI'!$B$11) -> 43391.162 | D16: =IF(A16="","",B16*'Loan EMI'!$B$9) -> 34711.794 | E16: =IF(A16="","",C16-D16) -> 8679.3678 | F16: =IF(A16="","",MAX(B16-E16,0)) -> 4891809.2
A17: =IF(14<='Loan EMI'!$B$10,14,"") -> 14 | B17: =IF(A17="","",F16) -> 4891809.2 | C17: =IF(A17="","",'Loan EMI'!$B$11) -> 43391.162 | D17: =IF(A17="","",B17*'Loan EMI'!$B$9) -> 34650.315 | E17: =IF(A17="","",C17-D17) -> 8740.8467 | F17: =IF(A17="","",MAX(B17-E17,0)) -> 4883068.3
A18: =IF(15<='Loan EMI'!$B$10,15,"") -> 15 | B18: =IF(A18="","",F17) -> 4883068.3 | C18: =IF(A18="","",'Loan EMI'!$B$11) -> 43391.162 | D18: =IF(A18="","",B18*'Loan EMI'!$B$9) -> 34588.401 | E18: =IF(A18="","",C18-D18) -> 8802.761 | F18: =IF(A18="","",MAX(B18-E18,0)) -> 4874265.6
A19: =IF(16<='Loan EMI'!$B$10,16,"") -> 16 | B19: =IF(A19="","",F18) -> 4874265.6 | C19: =IF(A19="","",'Loan EMI'!$B$11) -> 43391.162 | D19: =IF(A19="","",B19*'Loan EMI'!$B$9) -> 34526.048 | E19: =IF(A19="","",C19-D19) -> 8865.1139 | F19: =IF(A19="","",MAX(B19-E19,0)) -> 4865400.5
A20: =IF(17<='Loan EMI'!$B$10,17,"") -> 17 | B20: =IF(A20="","",F19) -> 4865400.5 | C20: =IF(A20="","",'Loan EMI'!$B$11) -> 43391.162 | D20: =IF(A20="","",B20*'Loan EMI'!$B$9) -> 34463.253 | E20: =IF(A20="","",C20-D20) -> 8927.9085 | F20: =IF(A20="","",MAX(B20-E20,0)) -> 4856472.5
A21: =IF(18<='Loan EMI'!$B$10,18,"") -> 18 | B21: =IF(A21="","",F20) -> 4856472.5 | C21: =IF(A21="","",'Loan EMI'!$B$11) -> 43391.162 | D21: =IF(A21="","",B21*'Loan EMI'!$B$9) -> 34400.014 | E21: =IF(A21="","",C21-D21) -> 8991.1478 | F21: =IF(A21="","",MAX(B21-E21,0)) -> 4847481.4
A22: =IF(19<='Loan EMI'!$B$10,19,"") -> 19 | B22: =IF(A22="","",F21) -> 4847481.4 | C22: =IF(A22="","",'Loan EMI'!$B$11) -> 43391.162 | D22: =IF(A22="","",B22*'Loan EMI'!$B$9) -> 34336.327 | E22: =IF(A22="","",C22-D22) -> 9054.8351 | F22: =IF(A22="","",MAX(B22-E22,0)) -> 4838426.6
A23: =IF(20<='Loan EMI'!$B$10,20,"") -> 20 | B23: =IF(A23="","",F22) -> 4838426.6 | C23: =IF(A23="","",'Loan EMI'!$B$11) -> 43391.162 | D23: =IF(A23="","",B23*'Loan EMI'!$B$9) -> 34272.188 | E23: =IF(A23="","",C23-D23) -> 9118.9735 | F23: =IF(A23="","",MAX(B23-E23,0)) -> 4829307.6
A24: =IF(21<='Loan EMI'!$B$10,21,"") -> 21 | B24: =IF(A24="","",F23) -> 4829307.6 | C24: =IF(A24="","",'Loan EMI'!$B$11) -> 43391.162 | D24: =IF(A24="","",B24*'Loan EMI'!$B$9) -> 34207.595 | E24: =IF(A24="","",C24-D24) -> 9183.5663 | F24: =IF(A24="","",MAX(B24-E24,0)) -> 4820124
A25: =IF(22<='Loan EMI'!$B$10,22,"") -> 22 | B25: =IF(A25="","",F24) -> 4820124 | C25: =IF(A25="","",'Loan EMI'!$B$11) -> 43391.162 | D25: =IF(A25="","",B25*'Loan EMI'!$B$9) -> 34142.545 | E25: =IF(A25="","",C25-D25) -> 9248.6165 | F25: =IF(A25="","",MAX(B25-E25,0)) -> 4810875.4
A26: =IF(23<='Loan EMI'!$B$10,23,"") -> 23 | B26: =IF(A26="","",F25) -> 4810875.4 | C26: =IF(A26="","",'Loan EMI'!$B$11) -> 43391.162 | D26: =IF(A26="","",B26*'Loan EMI'!$B$9) -> 34077.034 | E26: =IF(A26="","",C26-D26) -> 9314.1276 | F26: =IF(A26="","",MAX(B26-E26,0)) -> 4801561.3
A27: =IF(24<='Loan EMI'!$B$10,24,"") -> 24 | B27: =IF(A27="","",F26) -> 4801561.3 | C27: =IF(A27="","",'Loan EMI'!$B$11) -> 43391.162 | D27: =IF(A27="","",B27*'Loan EMI'!$B$9) -> 34011.059 | E27: =IF(A27="","",C27-D27) -> 9380.1026 | F27: =IF(A27="","",MAX(B27-E27,0)) -> 4792181.2
A28: =IF(25<='Loan EMI'!$B$10,25,"") -> 25 | B28: =IF(A28="","",F27) -> 4792181.2 | C28: =IF(A28="","",'Loan EMI'!$B$11) -> 43391.162 | D28: =IF(A28="","",B28*'Loan EMI'!$B$9) -> 33944.617 | E28: =IF(A28="","",C28-D28) -> 9446.545 | F28: =IF(A28="","",MAX(B28-E28,0)) -> 4782734.6
A29: =IF(26<='Loan EMI'!$B$10,26,"") -> 26 | B29: =IF(A29="","",F28) -> 4782734.6 | C29: =IF(A29="","",'Loan EMI'!$B$11) -> 43391.162 | D29: =IF(A29="","",B29*'Loan EMI'!$B$9) -> 33877.704 | E29: =IF(A29="","",C29-D29) -> 9513.4581 | F29: =IF(A29="","",MAX(B29-E29,0)) -> 4773221.2
A30: =IF(27<='Loan EMI'!$B$10,27,"") -> 27 | B30: =IF(A30="","",F29) -> 4773221.2 | C30: =IF(A30="","",'Loan EMI'!$B$11) -> 43391.162 | D30: =IF(A30="","",B30*'Loan EMI'!$B$9) -> 33810.317 | E30: =IF(A30="","",C30-D30) -> 9580.845 | F30: =IF(A30="","",MAX(B30-E30,0)) -> 4763640.3
A31: =IF(28<='Loan EMI'!$B$10,28,"") -> 28 | B31: =IF(A31="","",F30) -> 4763640.3 | C31: =IF(A31="","",'Loan EMI'!$B$11) -> 43391.162 | D31: =IF(A31="","",B31*'Loan EMI'!$B$9) -> 33742.452 | E31: =IF(A31="","",C31-D31) -> 9648.7094 | F31: =IF(A31="","",MAX(B31-E31,0)) -> 4753991.6
A32: =IF(29<='Loan EMI'!$B$10,29,"") -> 29 | B32: =IF(A32="","",F31) -> 4753991.6 | C32: =IF(A32="","",'Loan EMI'!$B$11) -> 43391.162 | D32: =IF(A32="","",B32*'Loan EMI'!$B$9) -> 33674.107 | E32: =IF(A32="","",C32-D32) -> 9717.0544 | F32: =IF(A32="","",MAX(B32-E32,0)) -> 4744274.6
A33: =IF(30<='Loan EMI'!$B$10,30,"") -> 30 | B33: =IF(A33="","",F32) -> 4744274.6 | C33: =IF(A33="","",'Loan EMI'!$B$11) -> 43391.162 | D33: =IF(A33="","",B33*'Loan EMI'!$B$9) -> 33605.278 | E33: =IF(A33="","",C33-D33) -> 9785.8835 | F33: =IF(A33="","",MAX(B33-E33,0)) -> 4734488.7
A34: =IF(31<='Loan EMI'!$B$10,31,"") -> 31 | B34: =IF(A34="","",F33) -> 4734488.7 | C34: =IF(A34="","",'Loan EMI'!$B$11) -> 43391.162 | D34: =IF(A34="","",B34*'Loan EMI'!$B$9) -> 33535.961 | E34: =IF(A34="","",C34-D34) -> 9855.2002 | F34: =IF(A34="","",MAX(B34-E34,0)) -> 4724633.5
A35: =IF(32<='Loan EMI'!$B$10,32,"") -> 32 | B35: =IF(A35="","",F34) -> 4724633.5 | C35: =IF(A35="","",'Loan EMI'!$B$11) -> 43391.162 | D35: =IF(A35="","",B35*'Loan EMI'!$B$9) -> 33466.154 | E35: =IF(A35="","",C35-D35) -> 9925.0079 | F35: =IF(A35="","",MAX(B35-E35,0)) -> 4714708.5
A36: =IF(33<='Loan EMI'!$B$10,33,"") -> 33 | B36: =IF(A36="","",F35) -> 4714708.5 | C36: =IF(A36="","",'Loan EMI'!$B$11) -> 43391.162 | D36: =IF(A36="","",B36*'Loan EMI'!$B$9) -> 33395.852 | E36: =IF(A36="","",C36-D36) -> 9995.31 | F36: =IF(A36="","",MAX(B36-E36,0)) -> 4704713.2
A37: =IF(34<='Loan EMI'!$B$10,34,"") -> 34 | B37: =IF(A37="","",F36) -> 4704713.2 | C37: =IF(A37="","",'Loan EMI'!$B$11) -> 43391.162 | D37: =IF(A37="","",B37*'Loan EMI'!$B$9) -> 33325.052 | E37: =IF(A37="","",C37-D37) -> 10066.11 | F37: =IF(A37="","",MAX(B37-E37,0)) -> 4694647
A38: =IF(35<='Loan EMI'!$B$10,35,"") -> 35 | B38: =IF(A38="","",F37) -> 4694647 | C38: =IF(A38="","",'Loan EMI'!$B$11) -> 43391.162 | D38: =IF(A38="","",B38*'Loan EMI'!$B$9) -> 33253.75 | E38: =IF(A38="","",C38-D38) -> 10137.412 | F38: =IF(A38="","",MAX(B38-E38,0)) -> 4684509.6
A39: =IF(36<='Loan EMI'!$B$10,36,"") -> 36 | B39: =IF(A39="","",F38) -> 4684509.6 | C39: =IF(A39="","",'Loan EMI'!$B$11) -> 43391.162 | D39: =IF(A39="","",B39*'Loan EMI'!$B$9) -> 33181.943 | E39: =IF(A39="","",C39-D39) -> 10209.218 | F39: =IF(A39="","",MAX(B39-E39,0)) -> 4674300.4
A40: =IF(37<='Loan EMI'!$B$10,37,"") -> 37 | B40: =IF(A40="","",F39) -> 4674300.4 | C40: =IF(A40="","",'Loan EMI'!$B$11) -> 43391.162 | D40: =IF(A40="","",B40*'Loan EMI'!$B$9) -> 33109.628 | E40: =IF(A40="","",C40-D40) -> 10281.534 | F40: =IF(A40="","",MAX(B40-E40,0)) -> 4664018.9
A41: =IF(38<='Loan EMI'!$B$10,38,"") -> 38 | B41: =IF(A41="","",F40) -> 4664018.9 | C41: =IF(A41="","",'Loan EMI'!$B$11) -> 43391.162 | D41: =IF(A41="","",B41*'Loan EMI'!$B$9) -> 33036.8 | E41: =IF(A41="","",C41-D41) -> 10354.361 | F41: =IF(A41="","",MAX(B41-E41,0)) -> 4653664.5
...

Sheet SIP Planner
A1: SIP (Systematic Investment Plan) Planner
A2: Edit only the blue cells with yellow fill. Returns are an assumption, not a guarantee.
A4: Monthly SIP amount | B4: 10000
A5: Expected annual return | B5: 0.12
A6: Investment period (years) | B6: 15
A7: Annual step-up in SIP | B7: 0
A9: Results
A10: Total invested | B10: =SUM(B19:B48) -> 1800000
A11: Final corpus value | B11: {=IFERROR(INDEX(E19:E48,B6),0)} -> 4759314
A12: Wealth gained | B12: =B11-B10 -> 2959314
A13: Corpus / invested (x) | B13: =IFERROR(B11/B10,0) -> 2.6440633
A14: Year-wise growth (monthly compounding; SIP invested at start of each month; step-up applied yearly).
A15: Monthly return used | B15: =(1+B5)^(1/12)-1 -> 0.0094887929
A18: Year | B18: Invested in year | C18: Cumulative invested | D18: Monthly SIP in year | E18: Corpus at year end
A19: =IF(1<=$B$6,1,"") -> 1 | B19: =IF(A19="","",D19*12) -> 120000 | C19: =IF(A19="","",SUM($B$19:B19)) -> 120000 | D19: =IF(A19="","",$B$4*(1+$B$7)^(1-1)) -> 10000 | E19: =IF(A19="","",0*(1+$B$15)^12+D19*((1+$B$15)^12-1)/$B$15*(1+$B$15)) -> 127664.98
A20: =IF(2<=$B$6,2,"") -> 2 | B20: =IF(A20="","",D20*12) -> 120000 | C20: =IF(A20="","",SUM($B$19:B20)) -> 240000 | D20: =IF(A20="","",$B$4*(1+$B$7)^(2-1)) -> 10000 | E20: =IF(A20="","",E19*(1+$B$15)^12+D20*((1+$B$15)^12-1)/$B$15*(1+$B$15)) -> 270649.76
A21: =IF(3<=$B$6,3,"") -> 3 | B21: =IF(A21="","",D21*12) -> 120000 | C21: =IF(A21="","",SUM($B$19:B21)) -> 360000 | D21: =IF(A21="","",$B$4*(1+$B$7)^(3-1)) -> 10000 | E21: =IF(A21="","",E20*(1+$B$15)^12+D21*((1+$B$15)^12-1)/$B$15*(1+$B$15)) -> 430792.71
A22: =IF(4<=$B$6,4,"") -> 4 | B22: =IF(A22="","",D22*12) -> 120000 | C22: =IF(A22="","",SUM($B$19:B22)) -> 480000 | D22: =IF(A22="","",$B$4*(1+$B$7)^(4-1)) -> 10000 | E22: =IF(A22="","",E21*(1+$B$15)^12+D22*((1+$B$15)^12-1)/$B$15*(1+$B$15)) -> 610152.81
A23: =IF(5<=$B$6,5,"") -> 5 | B23: =IF(A23="","",D23*12) -> 120000 | C23: =IF(A23="","",SUM($B$19:B23)) -> 600000 | D23: =IF(A23="","",$B$4*(1+$B$7)^(5-1)) -> 10000 | E23: =IF(A23="","",E22*(1+$B$15)^12+D23*((1+$B$15)^12-1)/$B$15*(1+$B$15)) -> 811036.13
A24: =IF(6<=$B$6,6,"") -> 6 | B24: =IF(A24="","",D24*12) -> 120000 | C24: =IF(A24="","",SUM($B$19:B24)) -> 720000 | D24: =IF(A24="","",$B$4*(1+$B$7)^(6-1)) -> 10000 | E24: =IF(A24="","",E23*(1+$B$15)^12+D24*((1+$B$15)^12-1)/$B$15*(1+$B$15)) -> 1036025.4
A25: =IF(7<=$B$6,7,"") -> 7 | B25: =IF(A25="","",D25*12) -> 120000 | C25: =IF(A25="","",SUM($B$19:B25)) -> 840000 | D25: =IF(A25="","",$B$4*(1+$B$7)^(7-1)) -> 10000 | E25: =IF(A25="","",E24*(1+$B$15)^12+D25*((1+$B$15)^12-1)/$B$15*(1+$B$15)) -> 1288013.5
A26: =IF(8<=$B$6,8,"") -> 8 | B26: =IF(A26="","",D26*12) -> 120000 | C26: =IF(A26="","",SUM($B$19:B26)) -> 960000 | D26: =IF(A26="","",$B$4*(1+$B$7)^(8-1)) -> 10000 | E26: =IF(A26="","",E25*(1+$B$15)^12+D26*((1+$B$15)^12-1)/$B$15*(1+$B$15)) -> 1570240.1
A27: =IF(9<=$B$6,9,"") -> 9 | B27: =IF(A27="","",D27*12) -> 120000 | C27: =IF(A27="","",SUM($B$19:B27)) -> 1080000 | D27: =IF(A27="","",$B$4*(1+$B$7)^(9-1)) -> 10000 | E27: =IF(A27="","",E26*(1+$B$15)^12+D27*((1+$B$15)^12-1)/$B$15*(1+$B$15)) -> 1886333.9
A28: =IF(10<=$B$6,10,"") -> 10 | B28: =IF(A28="","",D28*12) -> 120000 | C28: =IF(A28="","",SUM($B$19:B28)) -> 1200000 | D28: =IF(A28="","",$B$4*(1+$B$7)^(10-1)) -> 10000 | E28: =IF(A28="","",E27*(1+$B$15)^12+D28*((1+$B$15)^12-1)/$B$15*(1+$B$15)) -> 2240358.9
A29: =IF(11<=$B$6,11,"") -> 11 | B29: =IF(A29="","",D29*12) -> 120000 | C29: =IF(A29="","",SUM($B$19:B29)) -> 1320000 | D29: =IF(A29="","",$B$4*(1+$B$7)^(11-1)) -> 10000 | E29: =IF(A29="","",E28*(1+$B$15)^12+D29*((1+$B$15)^12-1)/$B$15*(1+$B$15)) -> 2636866.9
A30: =IF(12<=$B$6,12,"") -> 12 | B30: =IF(A30="","",D30*12) -> 120000 | C30: =IF(A30="","",SUM($B$19:B30)) -> 1440000 | D30: =IF(A30="","",$B$4*(1+$B$7)^(12-1)) -> 10000 | E30: =IF(A30="","",E29*(1+$B$15)^12+D30*((1+$B$15)^12-1)/$B$15*(1+$B$15)) -> 3080956
A31: =IF(13<=$B$6,13,"") -> 13 | B31: =IF(A31="","",D31*12) -> 120000 | C31: =IF(A31="","",SUM($B$19:B31)) -> 1560000 | D31: =IF(A31="","",$B$4*(1+$B$7)^(13-1)) -> 10000 | E31: =IF(A31="","",E30*(1+$B$15)^12+D31*((1+$B$15)^12-1)/$B$15*(1+$B$15)) -> 3578335.6
A32: =IF(14<=$B$6,14,"") -> 14 | B32: =IF(A32="","",D32*12) -> 120000 | C32: =IF(A32="","",SUM($B$19:B32)) -> 1680000 | D32: =IF(A32="","",$B$4*(1+$B$7)^(14-1)) -> 10000 | E32: =IF(A32="","",E31*(1+$B$15)^12+D32*((1+$B$15)^12-1)/$B$15*(1+$B$15)) -> 4135400.9
A33: =IF(15<=$B$6,15,"") -> 15 | B33: =IF(A33="","",D33*12) -> 120000 | C33: =IF(A33="","",SUM($B$19:B33)) -> 1800000 | D33: =IF(A33="","",$B$4*(1+$B$7)^(15-1)) -> 10000 | E33: =IF(A33="","",E32*(1+$B$15)^12+D33*((1+$B$15)^12-1)/$B$15*(1+$B$15)) -> 4759314
A34: =IF(16<=$B$6,16,"") | B34: =IF(A34="","",D34*12) | C34: =IF(A34="","",SUM($B$19:B34)) | D34: =IF(A34="","",$B$4*(1+$B$7)^(16-1)) | E34: =IF(A34="","",E33*(1+$B$15)^12+D34*((1+$B$15)^12-1)/$B$15*(1+$B$15))
A35: =IF(17<=$B$6,17,"") | B35: =IF(A35="","",D35*12) | C35: =IF(A35="","",SUM($B$19:B35)) | D35: =IF(A35="","",$B$4*(1+$B$7)^(17-1)) | E35: =IF(A35="","",E34*(1+$B$15)^12+D35*((1+$B$15)^12-1)/$B$15*(1+$B$15))
A36: =IF(18<=$B$6,18,"") | B36: =IF(A36="","",D36*12) | C36: =IF(A36="","",SUM($B$19:B36)) | D36: =IF(A36="","",$B$4*(1+$B$7)^(18-1)) | E36: =IF(A36="","",E35*(1+$B$15)^12+D36*((1+$B$15)^12-1)/$B$15*(1+$B$15))
A37: =IF(19<=$B$6,19,"") | B37: =IF(A37="","",D37*12) | C37: =IF(A37="","",SUM($B$19:B37)) | D37: =IF(A37="","",$B$4*(1+$B$7)^(19-1)) | E37: =IF(A37="","",E36*(1+$B$15)^12+D37*((1+$B$15)^12-1)/$B$15*(1+$B$15))
A38: =IF(20<=$B$6,20,"") | B38: =IF(A38="","",D38*12) | C38: =IF(A38="","",SUM($B$19:B38)) | D38: =IF(A38="","",$B$4*(1+$B$7)^(20-1)) | E38: =IF(A38="","",E37*(1+$B$15)^12+D38*((1+$B$15)^12-1)/$B$15*(1+$B$15))
A39: =IF(21<=$B$6,21,"") | B39: =IF(A39="","",D39*12) | C39: =IF(A39="","",SUM($B$19:B39)) | D39: =IF(A39="","",$B$4*(1+$B$7)^(21-1)) | E39: =IF(A39="","",E38*(1+$B$15)^12+D39*((1+$B$15)^12-1)/$B$15*(1+$B$15))
A40: =IF(22<=$B$6,22,"") | B40: =IF(A40="","",D40*12) | C40: =IF(A40="","",SUM($B$19:B40)) | D40: =IF(A40="","",$B$4*(1+$B$7)^(22-1)) | E40: =IF(A40="","",E39*(1+$B$15)^12+D40*((1+$B$15)^12-1)/$B$15*(1+$B$15))
A41: =IF(23<=$B$6,23,"") | B41: =IF(A41="","",D41*12) | C41: =IF(A41="","",SUM($B$19:B41)) | D41: =IF(A41="","",$B$4*(1+$B$7)^(23-1)) | E41: =IF(A41="","",E40*(1+$B$15)^12+D41*((1+$B$15)^12-1)/$B$15*(1+$B$15))
A42: =IF(24<=$B$6,24,"") | B42: =IF(A42="","",D42*12) | C42: =IF(A42="","",SUM($B$19:B42)) | D42: =IF(A42="","",$B$4*(1+$B$7)^(24-1)) | E42: =IF(A42="","",E41*(1+$B$15)^12+D42*((1+$B$15)^12-1)/$B$15*(1+$B$15))
A43: =IF(25<=$B$6,25,"") | B43: =IF(A43="","",D43*12) | C43: =IF(A43="","",SUM($B$19:B43)) | D43: =IF(A43="","",$B$4*(1+$B$7)^(25-1)) | E43: =IF(A43="","",E42*(1+$B$15)^12+D43*((1+$B$15)^12-1)/$B$15*(1+$B$15))
A44: =IF(26<=$B$6,26,"") | B44: =IF(A44="","",D44*12) | C44: =IF(A44="","",SUM($B$19:B44)) | D44: =IF(A44="","",$B$4*(1+$B$7)^(26-1)) | E44: =IF(A44="","",E43*(1+$B$15)^12+D44*((1+$B$15)^12-1)/$B$15*(1+$B$15))
...

Sheet Savings Comparison
A1: Where does ₹1,00,000 grow more? (5-year comparison)
A2: Rates are illustrative inputs - replace with current rates from the bank's website.
A4: Amount invested | B4: 100000
A5: Years | B5: 5
A7: Option | B7: Annual rate | C7: Compounding per year | D7: Maturity value | E7: Gain
A8: Savings account (illustrative) | B8: 0.03 | C8: 4 | D8: =$B$4*(1+B8/C8)^(C8*$B$5) -> 116118.41 | E8: =D8-$B$4 -> 16118.414
A9: Fixed deposit (illustrative) | B9: 0.07 | C9: 4 | D9: =$B$4*(1+B9/C9)^(C9*$B$5) -> 141477.82 | E9: =D9-$B$4 -> 41477.82
A10: Debt mutual fund (illustrative) | B10: 0.075 | C10: 1 | D10: =$B$4*(1+B10/C10)^(C10*$B$5) -> 143562.93 | E10: =D10-$B$4 -> 43562.933
A11: Equity mutual fund (illustrative) | B11: 0.12 | C11: 1 | D11: =$B$4*(1+B11/C11)^(C11*$B$5) -> 176234.17 | E11: =D11-$B$4 -> 76234.168
A13: Equity returns are not assured and carry market risk. For learning purposes only.
